Workbook
Name _Order1: 255
Name _Order2: 255
Name FWS: [1]参数表!$C$2:$C$6
Name XQ: [1]参数表!$B$2:$B$9
Name 厨卫规格: [2]参数!$F$2:$F$11
Name 单位用量: '[3]1-1 定额【5.0】'!$O:$O
Name 单位用量: '[4]1-1 定额【5.0】'!$O:$O
Name 辅材材料单价: '[3]1-1 定额【5.0】'!$S:$S
Name 辅材材料单价: '[4]1-1 定额【5.0】'!$S:$S
Name 辅材采购损耗率: '[3]1-1 定额【5.0】'!$P:$P
Name 辅材采购损耗率: '[4]1-1 定额【5.0】'!$P:$P
Name 辅材施工损耗率: '[3]1-1 定额【5.0】'!$R:$R
Name 辅材施工损耗率: '[4]1-1 定额【5.0】'!$R:$R
Name 辅材运输损耗率: '[3]1-1 定额【5.0】'!$Q:$Q
Name 辅材运输损耗率: '[4]1-1 定额【5.0】'!$Q:$Q
Name 户型: [2]参数!$G$2:$G$14
Name 水电套餐: [2]参数!$D$2:$D$4
Name 水电套餐品牌: [2]参数!$E$2:$E$6
Name 状态: [2]参数!$H$2:$H$8

Sheet 基装
B1: 工程预算清单 | K1: 项目编号：
A2: 序号 | B2: 项目名称 | C2: 单位 | D2: 物料编码 | E2: 主材损耗率 | F2: 主材单价 | G2: 施工单价 | H2: 工程量 | I2: 小计 | J2: 计算规则 | K2: 项目特征描述
A3: 一 | I3: =SUM(I4:I22) -> 0
A4: =+ROW()-ROW($A$3) -> 1 | B4: 墙体拆除（120墙） | C4: =VLOOKUP(B4,'报价表 最新'!A:B,2,0) -> 平米 | J4: =VLOOKUP(B4,'报价表 最新'!A:F,4,0) -> 按拆除面积计算，厚度超出部分按比例折算 | K4: =VLOOKUP(B4,'报价表 最新'!A:F,5,0) -> 拆除120墙体
A5: =+ROW()-ROW($A$3) -> 2 | B5: 墙体拆除（240墙） | C5: =VLOOKUP(B5,'报价表 最新'!A:B,2,0) -> 平米 | J5: =VLOOKUP(B5,'报价表 最新'!A:F,4,0) -> 按拆除面积计算，厚度超出部分按比例折算 | K5: =VLOOKUP(B5,'报价表 最新'!A:F,5,0) -> 拆除240墙体
A6: =+ROW()-ROW($A$3) -> 3 | B6: 拆除保温层 | C6: =VLOOKUP(B6,'报价表 最新'!A:B,2,0) -> 平米 | J6: =VLOOKUP(B6,'报价表 最新'!A:F,4,0) -> 按拆除面积计算 | K6: =VLOOKUP(B6,'报价表 最新'!A:F,5,0) -> 拆除保温层或外墙漆
A7: =+ROW()-ROW($A$3) -> 4 | B7: 拆除外墙砖 | C7: =VLOOKUP(B7,'报价表 最新'!A:B,2,0) -> 平米 | J7: =VLOOKUP(B7,'报价表 最新'!A:F,4,0) -> 按拆除面积计算 | K7: =VLOOKUP(B7,'报价表 最新'!A:F,5,0) -> 拆除外墙砖
A8: =+ROW()-ROW($A$3) -> 5 | B8: 拆除室外/室内混凝土楼梯 | C8: =VLOOKUP(B8,'报价表 最新'!A:B,2,0) -> 步 | J8: =VLOOKUP(B8,'报价表 最新'!A:F,4,0) -> 按踏步数计算 | K8: =VLOOKUP(B8,'报价表 最新'!A:F,5,0) -> 包含室外/室内楼梯拆除、现场清理
A9: =+ROW()-ROW($A$3) -> 6 | B9: 门窗、栏杆拆除 | C9: =VLOOKUP(B9,'报价表 最新'!A:B,2,0) -> 米 | J9: =VLOOKUP(B9,'报价表 最新'!A:F,4,0) -> 1.按拆除米数计算 2.最低收费2米 3.客户不要的工人自行处理，不予收费 | K9: =VLOOKUP(B9,'报价表 最新'!A:F,5,0) -> 拆除门、门套及门套基层，拆除防护栏杆
A10: =+ROW()-ROW($A$3) -> 7 | B10: 新建60墙（红砖） | C10: =VLOOKUP(B10,'报价表 最新'!A:B,2,0) -> 平米 | J10: =VLOOKUP(B10,'报价表 最新'!A:F,4,0) -> 按新建面积计算 | K10: =VLOOKUP(B10,'报价表 最新'!A:F,5,0) -> 包含铲墙皮、植筋、墙体砌筑、新旧墙体交接处挂网、墙面抹灰
A11: =+ROW()-ROW($A$3) -> 8 | B11: 新建120墙（红砖） | C11: 平米 | J11: =VLOOKUP(B11,'报价表 最新'!A:F,4,0) -> 按新建面积计算 主要用于厨卫、生活阳台及承重区域 | K11: =VLOOKUP(B11,'报价表 最新'!A:F,5,0) -> 包含铲墙皮、植筋、墙体砌筑、新旧墙体交接处挂网、墙面抹灰
A12: 9 | B12: 新建120弧形墙（红砖） | C12: 平米 | J12: =VLOOKUP(B12,'报价表 最新'!A:F,4,0) -> 按新建面积计算 主要用于厨卫、生活阳台及承重区域 | K12: =VLOOKUP(B12,'报价表 最新'!A:F,5,0) -> 包含铲墙皮、植筋、墙体砌筑、新旧墙体交接处挂网、墙面抹灰
A13: =+ROW()-ROW($A$3) -> 10 | B13: 新建240墙（红砖） | C13: =VLOOKUP(B13,'报价表 最新'!A:B,2,0) -> 平米 | J13: =VLOOKUP(B13,'报价表 最新'!A:F,4,0) -> 按新建面积计算 主要用于厨卫、生活阳台及承重区域 | K13: =VLOOKUP(B13,'报价表 最新'!A:F,5,0) -> 包含铲墙皮、植筋、墙体砌筑、新旧墙体交接处挂网、墙面抹灰
A14: =+ROW()-ROW($A$3) -> 11 | B14: 门窗洞修补（水泥砂浆） | C14: =VLOOKUP(B14,'报价表 最新'!A:B,2,0) -> 个 | J14: =VLOOKUP(B14,'报价表 最新'!A:F,4,0) -> 按个数计算 | K14: =VLOOKUP(B14,'报价表 最新'!A:F,5,0) -> 水泥砂浆抹灰修补，适用于打拆后的门窗洞修补，不含过梁
A15: =+ROW()-ROW($A$3) -> 12 | B15: 新建单边门垛（200mm宽以内） | C15: =VLOOKUP(B15,'报价表 最新'!A:B,2,0) -> 个 | J15: =VLOOKUP(B15,'报价表 最新'!A:F,4,0) -> 按个数计算 | K15: =VLOOKUP(B15,'报价表 最新'!A:F,5,0) -> 包含植筋、墙体砌筑、新旧墙体交接处挂网
A16: =+ROW()-ROW($A$3) -> 13 | B16: 新建壁龛 | C16: =VLOOKUP(B16,'报价表 最新'!A:B,2,0) -> 格 | J16: =VLOOKUP(B16,'报价表 最新'!A:F,4,0) -> 按个数计算 | K16: =VLOOKUP(B16,'报价表 最新'!A:F,5,0) -> 包含墙体砌筑、新旧墙体交接处挂网
A17: =+ROW()-ROW($A$3) -> 14 | B17: 门过梁施工（1.2米） | C17: =VLOOKUP(B17,'报价表 最新'!A:B,2,0) -> 根 | J17: =VLOOKUP(B17,'报价表 最新'!A:F,4,0) -> 按根数计算，墙厚140mm以内的墙使用1根，墙厚>140mm的墙使用2根 | K17: =VLOOKUP(B17,'报价表 最新'!A:F,5,0) -> 门洞宽900mm以内
A18: =+ROW()-ROW($A$3) -> 15 | B18: 门过梁施工（2米） | C18: =VLOOKUP(B18,'报价表 最新'!A:B,2,0) -> 根 | J18: =VLOOKUP(B18,'报价表 最新'!A:F,4,0) -> 按根数计算，墙厚140mm以内的墙使用1根，墙厚>140mm的墙使用2根 | K18: =VLOOKUP(B18,'报价表 最新'!A:F,5,0) -> 门洞宽1600mm以内
A19: =+ROW()-ROW($A$3) -> 16 | B19: 门钢架过梁施工（3米） | C19: =VLOOKUP(B19,'报价表 最新'!A:B,2,0) -> 根 | J19: =VLOOKUP(B19,'报价表 最新'!A:F,4,0) -> 按根数计算，墙厚140mm以内的墙使用1根，墙厚>140mm的墙使用2根 | K19: =VLOOKUP(B19,'报价表 最新'!A:F,5,0) -> 门洞宽度大于2米小于2.6米的
A20: =+ROW()-ROW($A$3) -> 17 | B20: 门套木基层 | C20: =VLOOKUP(B20,'报价表 最新'!A:B,2,0) -> 米 | J20: =VLOOKUP(B20,'报价表 最新'!A:F,4,0) -> 按延长米计算 | K20: =VLOOKUP(B20,'报价表 最新'!A:F,5,0) -> 门套基层制作及安装
A21: =+ROW()-ROW($A$3) -> 18 | B21: 双排钢架隔墙（暗藏式门基层含双面封板） | C21: =VLOOKUP(B21,'报价表 最新'!A:B,2,0) -> 平米 | J21: =VLOOKUP(B21,'报价表 最新'!A:F,4,0) -> 按施工面积计算 | K21: =VLOOKUP(B21,'报价表 最新'!A:F,5,0) -> 双排钢架隔墙及双面封基层板施工
A22: =+ROW()-ROW($A$3) -> 19 | B22: 空鼓拆除及修复 | C22: =VLOOKUP(B22,'报价表 最新'!A:B,2,0) -> 平米 | J22: =VLOOKUP(B22,'报价表 最新'!A:F,4,0) -> 单处空鼓面积小于1㎡按1㎡计算，大于1㎡按实际面积计算 | K22: =VLOOKUP(B22,'报价表 最新'!A:F,5,0) -> 空鼓拆除及修复处理等
A23: 二
A24: 1 | B24: 别墅水电全改（进口PPR） | C24: =VLOOKUP(B24,'报价表 最新'!A:B,2,0) -> 平米 | J24: =VLOOKUP(B24,'报价表 最新'!A:F,4,0) -> 按合同面积计算，超出标准部分，费用计算规则详见《水电计价标准》 | K24: =VLOOKUP(B24,'报价表 最新'!A:F,5,0) -> 包含开槽、开孔、强弱电改造、空开关调试、给排水改造、通水通电测试等
A25: 三
A26: =+ROW()-ROW(A25) -> 1 | B26: 陶粒回填+保护层 | C26: =VLOOKUP(B26,'报价表 最新'!A:B,2,0) -> 立方 | J26: =VLOOKUP(B26,'报价表 最新'!A:F,4,0) -> 按回填方量计算 | K26: =VLOOKUP(B26,'报价表 最新'!A:F,5,0) -> 陶粒回填找平
A27: =+ROW()-ROW(A25) -> 2 | B27: 水泥砂浆精找平 | C27: =VLOOKUP(B27,'报价表 最新'!A:B,2,0) -> 平米 | J27: =VLOOKUP(B27,'报价表 最新'!A:F,4,0) -> 按施工面积计算 找平厚度30mm以内，超出部分每增加10mm厚增加15元/平米 | K27: =VLOOKUP(B27,'报价表 最新'!A:F,5,0) -> 水泥砂浆找平，找平厚度≤30mm
A28: =+ROW()-ROW(A25) -> 3 | B28: 实木地板安装 | C28: =VLOOKUP(B28,'报价表 最新'!A:B,2,0) -> 平米 | E28: 0.05 | J28: =VLOOKUP(B28,'报价表 最新'!A:F,4,0) -> 按施工面积计算 | K28: =VLOOKUP(B28,'报价表 最新'!A:F,5,0) -> 含安装地垫、木地板、配件安装，完工保护等
A29: =+ROW()-ROW(A25) -> 4 | B29: 踢脚线安装 | C29: =VLOOKUP(B29,'报价表 最新'!A:B,2,0) -> 米 | E29: 0.07 | J29: =VLOOKUP(B29,'报价表 最新'!A:F,4,0) -> 按延长米计算 | K29: =VLOOKUP(B29,'报价表 最新'!A:F,5,0) -> 含安装踢脚线、打胶等
A30: =+ROW()-ROW(A25) -> 5 | B30: 地板收口条 | C30: 根 | J30: 按根数计算
A31: =+ROW()-ROW(A25) -> 6 | B31: 墙面石膏腻子顺平处理(干区) | C31: =VLOOKUP(B31,'报价表 最新'!A:B,2,0) -> 平米 | J31: =VLOOKUP(B31,'报价表 最新'!A:F,4,0) -> 按施工面积计算，门窗面积按50%计算 | K31: =VLOOKUP(B31,'报价表 最新'!A:F,5,0) -> 刷界面剂、挂网、补钉眼、铲胶、贴纸胶带、石膏找平、阴阳角处理、两遍腻子施工、打磨和一遍底漆施工等
A32: =+ROW()-ROW(A25) -> 7 | B32: 乳胶漆喷涂 | C32: =VLOOKUP(B32,'报价表 最新'!A:B,2,0) -> 平米 | D32: 纯净520A+竹炭抗菌五合一（喷涂） | J32: =VLOOKUP(B32,'报价表 最新'!A:F,4,0) -> 按施工面积计算 分色费另计 | K32: =VLOOKUP(B32,'报价表 最新'!A:F,5,0) -> 面漆喷涂施工
A33: =+ROW()-ROW(A25) -> 8 | B33: 窗台石安装 | C33: =VLOOKUP(B33,'报价表 最新'!A:B,2,0) -> 米 | J33: =VLOOKUP(B33,'报价表 最新'!A:F,4,0) -> 按延长米计算 | K33: =VLOOKUP(B33,'报价表 最新'!A:F,5,0) -> 成品安装
A34: =+ROW()-ROW(A25) -> 9 | B34: 轻钢龙骨单层石膏板吊顶（边顶） | C34: =VLOOKUP(B34,'报价表 最新'!A:B,2,0) -> 平米 | J34: =VLOOKUP(B34,'报价表 最新'!A:F,4,0) -> 按展开面积计算 | K34: =VLOOKUP(B34,'报价表 最新'!A:F,5,0) -> 包含打眼、吊筋、主副龙骨、单层石膏板安装、转角加固等
A35: =+ROW()-ROW(A25) -> 10 | B35: 吊顶眉线 | C35: =VLOOKUP(B35,'报价表 最新'!A:B,2,0) -> 米 | J35: =VLOOKUP(B35,'报价表 最新'!A:F,4,0) -> 按延长米计算 （宽度20mm以内，高度200mm以内，超出费用另计。高度每增加100mm增加15元/米） | K35: =VLOOKUP(B35,'报价表 最新'!A:F,5,0) -> 包含吊顶一圈、边顶或灯槽反边的眉线制作安装双层石膏板制作及安装（吊顶单算，这个只是眉线）
A36: =+ROW()-ROW(A25) -> 11 | B36: 窗帘盒 | C36: =VLOOKUP(B36,'报价表 最新'!A:B,2,0) -> 米 | J36: =VLOOKUP(B36,'报价表 最新'!A:F,4,0) -> 按延长米计算 | K36: =VLOOKUP(B36,'报价表 最新'!A:F,5,0) -> 包含窗帘盒制作安装、基层加固等
A37: =+ROW()-ROW(A25) -> 12 | B37: 开设备孔（空调/浴霸/暖风机） | C37: =VLOOKUP(B37,'报价表 最新'!A:B,2,0) -> 米 | J37: =VLOOKUP(B37,'报价表 最新'!A:F,4,0) -> 按米数计算，单个设备孔最低收费1米 | K37: =VLOOKUP(B37,'报价表 最新'!A:F,5,0) -> 包含放线、定位、开孔及加固处理等
A38: =+ROW()-ROW(A25) -> 13 | B38: 顶面石膏腻子顺平处理（干区） | C38: =VLOOKUP(B38,'报价表 最新'!A:B,2,0) -> 平米 | J38: =VLOOKUP(B38,'报价表 最新'!A:F,4,0) -> 按施工面积计算，门窗面积按50%计算 | K38: =VLOOKUP(B38,'报价表 最新'!A:F,5,0) -> 刷界面剂、挂网、补钉眼、铲胶、贴纸胶带、石膏找平、阴阳角处理、两遍腻子施工、打磨和一遍底漆施工等
A39: =+ROW()-ROW(A25) -> 14 | B39: 乳胶漆喷涂 | C39: =VLOOKUP(B39,'报价表 最新'!A:B,2,0) -> 平米 | D39: 纯净520防霉防潮三合一环保内墙漆 | J39: =VLOOKUP(B39,'报价表 最新'!A:F,4,0) -> 按施工面积计算 分色费另计 | K39: =VLOOKUP(B39,'报价表 最新'!A:F,5,0) -> 面漆喷涂施工
A40: =+ROW()-ROW(A25) -> 15 | B40: 平开门（含门套、门、五金） | C40: =VLOOKUP(B40,'报价表 最新'!A:B,2,0) -> 套 | D40: M2平开门 | J40: =VLOOKUP(B40,'报价表 最新'!A:F,4,0) -> 按套数计算 | K40: =VLOOKUP(B40,'报价表 最新'!A:F,5,0) -> 成品安装(含门套、门、五金)
...

Sheet 报价表 最新
A2: 施工内容 | B2: 单位 | C2: 售价 | G2: 定额组编码
C3: 售价 | D3: 计算规则 | E3: 项目特征描述 | F3: 工艺标准
A4: 成品保护+安全防护 | B4: 平米 | C4: 15 | D4: 按合同面积计算 | E4: 成品保护包含入场检查，电梯厅、走廊、过道、门窗、气表、水表、烟感、可视电话等的保护，包含挂安全网及其他辅材综合考虑 | F4: 1.成品保护工艺：清扫墙地面→喜鹊字样胶带固定保护膜（电梯间膜、门窗保护膜、燃气表保护罩）→强弱电箱保护→施工自检； 合格标准：电梯、电梯厅、走廊、门窗、天然气表、强弱电箱等粘贴保护，要求平整方正，方向正确，且无翘脚； 2.安全防护工艺：关闭水电总闸→更换水龙头→接临时电箱→接临时照明→挂阳台安全网防护→施工自检； 合格标准：临时水电做好防漏防渗保护，安全网无漏洞或破损，安全网固定在安全挂钩上，无漏挂，安全网牢固无松动现象。 | G4: =#REF! -> #REF!
A5: 包管道隔音棉 | B5: 根 | C5: 50 | D5: 按根数计算 | E5: 排水管包隔音棉、扎带 | F5: 1.包管工艺：主给排水管道（含天花顶部的存水弯）隔音棉包裹→施工自检。 | G5: =#REF! -> #REF!
A6: 安全防护 | B6: 平米 | C6: 5 | D6: 按合同面积计算 | E6: 1.安全网种类、规格：安全网 2.其他辅材综合考虑 | F6: 1.安全防护工艺：关闭水电总闸→更换水龙头→接临时电箱→接临时照明→挂阳台安全网防护→施工自检； 2.合格标准：临时水电做好防漏防渗保护，安全网无漏洞或破损，安全网固定在安全挂钩上，无漏挂，安全网牢固无松动现象。 | G6: =#REF! -> #REF!
A7: 硬保护 | B7: 平米 | C7: 40 | D7: 按施工面积计算，最低收费400元 | E7: 施工区域及施工涉及到的活动区域地面3mm中纤板保护，地板区域的地面需做硬保护 | F7: 按物业或客户要求进行现场保护 | G7: =#REF! -> #REF!
A8: 铲墙皮 | B8: 平米 | C8: 18 | D8: 按合同面积计算 | E8: 包含原墙面顶面乳胶漆及基层的铲除、清理建渣等 | F8: 1.铲墙皮工艺：断水断电→接通临水临电→喷水枪湿润墙面反复3次→铲刀铲除白灰→施工自检；（不含保温层、外墙砖等的拆除） 2.合格标准：白灰剔除干净，能看见水泥基层，墙面剔除达率到95%以上。 | G8: =#REF! -> #REF!
A9: 涂刷墙地固 | B9: 平米 | C9: 8 | D9: 按合同面积计算 | E9: 滚刷墙地固 | F9: 1.刷墙地固工艺：清扫地面墙面→安全防范→准备喷涂工具→墙地面全部喷涂→细部涂刷修补→地面涂刷延墙面往上100mm→施工自检； 2.合格标准：顶面、墙面、地面满涂墙地固，角落位置涂刷到位，涂刷均匀无漏涂。 | G9: =#REF! -> #REF!
A10: 精放线 | B10: 平米 | C10: 9 | D10: 按合同面积计算 | E10: 放水平线、中轴线、规方线、完成面线、吊顶线、新建墙体线、门洞定位线、点位线等 | F10: 1.精放线标准：包含施工工具准备、放水平线、中轴线、完成面线、吊顶线、新建墙体线、门洞定位线、点位喷漆等。 | G10: =#REF! -> #REF!
A11: 成品保护、铲墙皮、刷墙地固 | B11: 平米 | C11: 52 | D11: 按合同面积计算 | E11: 1.成品保护包含入场检查，电梯厅、走廊、过道、门窗、气表、水表、烟感、可视电话等的保护，管道包隔音棉处理，安全防护 2.铲墙皮（包含墙面和顶面） 3.墙地顶面涂刷界面剂 4.临水临电及精放线等施工准备工作 | F11: 1.成品保护工艺：清扫墙地面→喜鹊字样胶带固定保护膜（电梯间膜、门窗保护膜、燃气表保护罩）→主给排水管道（含天花顶部的存水弯）隔音棉包裹→强弱电箱保护→施工自检； 合格标准：电梯、电梯厅、走廊、门窗、天然气表、强弱电箱等粘贴保护，要求平整方正，方向正确，且无翘脚； 2.安全防护工艺：关闭水电总闸→更换水龙头→接临时电箱→接临时照明→挂阳台安全网防护→施工自检； 合格标准：临时水电做好防漏防渗保护，安全网无漏洞或破损，安全网固定在安全挂钩上，无漏挂，安全网牢固无松动现象； 3.铲墙皮工艺：断水断电→接通临水临电→喷水枪湿润墙面反复3次→铲刀铲除白灰→施工自检；（不含保温层、外墙砖等的拆除） 合格标准：白灰剔除干净，能看见水泥基层，墙面剔除达率到95%以上； 4.刷墙地固工艺：清扫地面墙面→安全防范→准备喷涂工具→墙地面全部喷涂→细部涂刷修补→地面涂刷延墙面往上100mm→施工自检； 合格标准：顶面、墙面、地面满涂墙地固，角落位置涂刷到位，涂刷均匀无漏涂； 5.精放线标准：包含施工工具准备、放水平线、中轴线、完成面线、吊顶线、新建墙体线、门洞定位线、点位喷漆等。 | G11: =#REF! -> #REF!
A12: 成品保护、刷墙地固 | B12: 平米 | C12: 44 | D12: 按合同面积计算 | E12: 1.成品保护包含入场检查，电梯厅、走廊、过道、门窗、气表、水表、烟感、可视电话等的保护，管道包隔音棉处理，安全防护 2.墙地顶面刷界面剂 3.临水临电及精放线等施工准备工作 | F12: 1.成品保护工艺：清扫墙地面→喜鹊字样胶带固定保护膜（电梯间膜、门窗保护膜、燃气表保护罩）→主给排水管道（含天花顶部的存水弯）隔音棉包裹→强弱电箱保护→施工自检； 合格标准：电梯、电梯厅、走廊、门窗、天然气表、强弱电箱等粘贴保护，要求平整方正，方向正确，且无翘脚； 2.安全防护工艺：关闭水电总闸→更换水龙头→接临时电箱→接临时照明→挂阳台安全网防护→施工自检； 合格标准：临时水电做好防漏防渗保护，安全网无漏洞或破损，安全网固定在安全挂钩上，无漏挂，安全网牢固无松动现象； 3.刷墙地固工艺：清扫地面墙面→安全防范→准备喷涂工具→墙地面全部喷涂→细部涂刷修补→地面涂刷延墙面往上100mm→施工自检 合格标准：顶面、墙面、地面满涂墙地固，角落位置涂刷到位，涂刷均匀无漏涂； 4.精放线标准：包含施工工具准备、放水平线、中轴线、完成面线、吊顶线、新建墙体线、门洞定位线、点位喷漆等。 | G12: =#REF! -> #REF!
A13: 墙体拆除（120墙） | B13: 平米 | C13: 70 | D13: 按拆除面积计算，厚度超出部分按比例折算 | E13: 拆除120墙体 | F13: 1.工艺：核对图纸→放线定位→根据拆除线使用切割机切割后拆除→建渣装袋→清理现场→施工自检； 2.合格标准：打拆前用角磨机先进行切割(防止二次空鼓)；拆除彻底，不残留不遗漏；现场垃圾清理干净，5S维护。 | G13: =#REF! -> #REF!
A14: 墙体拆除（240墙） | B14: 平米 | C14: 85 | D14: 按拆除面积计算，厚度超出部分按比例折算 | E14: 拆除240墙体 | F14: 1.工艺：核对图纸→放线定位→根据拆除线使用切割机切割后拆除→建渣装袋→清理现场→施工自检； 2.合格标准：打拆前用角磨机先进行切割(防止二次空鼓)；拆除彻底，不残留不遗漏；现场垃圾清理干净，5S维护。 | G14: =#REF! -> #REF!
A15: 拆除保温层 | B15: 平米 | C15: 25 | D15: 按拆除面积计算 | E15: 拆除保温层或外墙漆 | F15: 1.工艺：核对图纸→放线定位→（人工+机械）拆除→建渣装袋→清理现场→施工自检； 2.合格标准：打拆前用角磨机先进行切割(防止二次空鼓)；拆除彻底，不残留不遗漏；现场垃圾清理干净，5S维护。 | G15: =#REF! -> #REF!
... A42: 新建360墙（轻质砖） | B42: 平米 | C42: 450 | D42: 按新建面积计算 主要用于厨卫及生活阳台以外的非承重区域 | E42: 包含铲墙皮、植筋、墙体砌筑、新旧墙体交接处挂网、墙面抹灰 | F42: 1.工艺：定位放线→砂浆制拌→砌砖→勾缝、清理→墙面抹灰→施工自检（依据GB50203-2011《砌体工程施工质量验收规范》） 2.合格标准：墙体砖必须错缝1/3修砌、墙体底部以原始地面为基准线砌3层实心砖打底、如湿区墙体在沉箱内的则实心砖打底平齐客厅地面后再往上做3层实心砖、距离顶面80mm-150mm做斜砖蜈蚣脚、墙体间隔500mm做植筋、新旧墙面交界处做挂网处理（网面宽度150mm-200mm）、墙面平整垂直度≤4mm； | G42: =#REF! -> #REF!
A43: 新建单边门垛（200mm宽以内） | B43: 个 | C43: 200 | D43: 按个数计算 | E43: 包含植筋、墙体砌筑、新旧墙体交接处挂网 | F43: 0 | G43: =#REF! -> #REF!
A44: 门窗洞修补（水泥砂浆） | B44: 个 | C44: 150 | D44: 按个数计算 | E44: 水泥砂浆抹灰修补，适用于打拆后的门窗洞修补，不含过梁 | F44: 1.工艺：定位放线→砂浆制拌→砌砖（多孔砖、实心砖、空心砖、加气砖等）→勾缝、清理→施工自检（依据GB50203-2011《砌体工程施工质量验收规范》） 2.合格标准：墙体砖必须错缝1/3修砌、墙体底部以原始地面为基准线砌3层实心砖打底、如湿区墙体在沉箱内的则实心砖打底平齐客厅地面后再往上做3层实心砖、距离顶面80mm-150mm做斜砖蜈蚣脚、墙体间隔500mm做植筋、新旧墙面交界处做挂网处理（网面宽度150mm-200mm）、修补后垂直度误差≤5mm。 | G44: =#REF! -> #REF!
A45: 断面修补 | B45: 米 | C45: 40 | D45: 按延长米数计算 | E45: 0 | F45: 0 | G45: =#REF! -> #REF!
A46: 门过梁施工（1.2米） | B46: 根 | C46: 90 | D46: 按根数计算，墙厚140mm以内的墙使用1根，墙厚>140mm的墙使用2根 | E46: 门洞宽900mm以内 | F46: 1.测量定位→成品过梁安装→水泥砂浆固定→施工自检； 2.合格标准：过梁嵌入墙体两侧分别至少100mm。 | G46: =#REF! -> #REF!
A47: 门过梁施工（1.5米） | B47: 根 | C47: 100 | D47: 按根数计算，墙厚140mm以内的墙使用1根，墙厚>140mm的墙使用2根 | E47: 门洞宽1200mm以内 | F47: 1.测量定位→成品过梁安装→水泥砂浆固定→施工自检； 2.合格标准：过梁嵌入墙体两侧分别至少100mm。 | G47: =#REF! -> #REF!
A48: 门过梁施工（2米） | B48: 根 | C48: 110 | D48: 按根数计算，墙厚140mm以内的墙使用1根，墙厚>140mm的墙使用2根 | E48: 门洞宽1600mm以内 | F48: 1.测量定位→成品过梁安装→水泥砂浆固定→施工自检； 2.合格标准：过梁嵌入墙体两侧分别至少100mm。 | G48: =#REF! -> #REF!
A49: 门钢架过梁施工（3米） | B49: 根 | C49: 150 | D49: 按根数计算，墙厚140mm以内的墙使用1根，墙厚>140mm的墙使用2根 | E49: 门洞宽度大于2米小于2.6米的 | F49: 1.测量定位→L角钢架过梁安装→固定→施工自检； 2.合格标准：过梁嵌入墙体两侧分别至少100mm。 | G49: =#REF! -> #REF!
A50: 空鼓拆除及修复 | B50: 平米 | C50: 75 | D50: 单处空鼓面积小于1㎡按1㎡计算，大于1㎡按实际面积计算 | E50: 空鼓拆除及修复处理等 | F50: 1.工艺：切割机切割墙皮→剔除抹灰面层→水泥砂浆粗找平→施工自检； 2.合格标准：割墙皮应横平竖直切（防止引发周边墙皮松动空鼓）、剔除抹灰层至砖体，要求抹灰层剔除干净能看见砖墙基层，墙面剔除达率到95%以上；现场垃圾清理干净，5S维护，修复完成后墙面抹灰垂直度≤3mm，平整度≤4mm。 | G50: =#REF! -> #REF!
A51: 原建筑补烂修复 | B51: 平米 | C51: 50 | D51: 按施工面积计算 | E51: 打拆之后的门窗洞及墙地面用水泥砂浆抹平，或剔除最高点后修复处理等 | F51: 1.工艺： 湿区空鼓修复：在墙面标注需剔除空鼓的位置→切割拆除→涂刷瓷砖胶→水泥砂浆找平修复→现场清理→施工自检； 干区空鼓修复：在墙面标注需剔除空鼓的位置→切割拆除→涂刷界面剂→石膏找平修复→现场清理→施工自检； 2.合格标准：完成面平整度标准≤2mm。 | G51: =#REF! -> #REF!
A52: 新建壁龛 | B52: 格 | C52: 100 | D52: 按个数计算 | E52: 包含墙体砌筑、新旧墙体交接处挂网 | F52: 0 | G52: =#REF! -> #REF!
A53: 浴缸基座（砌体） | B53: 个 | C53: 1980 | D53: 2米以内按个数计算 超出部分按150元/10cm计算 | E53: 新建浴缸基座+抹灰+涂刷防水涂料+预留检修口（面材的主材和施工单独计算，不含浴缸的供应安装） | F53: 1.工艺：定位放线→砂浆制拌→砌砖→抹灰→防水→现场清理→施工自检； 2.合格标准：符合施工图要求，预留检修口。 | G53: =#REF! -> #REF!
A54: 浴缸基座（钢架） | B54: 个 | C54: 2450 | D54: 2米以内按个数计算 超出部分按200元/10cm计算 | E54: 焊接浴缸钢架基座+涂刷防锈漆+涂刷防水涂料+预留检修口（面材的主材和施工单独计算，不含浴缸的供应安装） | F54: 1.工艺：定位放线→钢管裁切、焊接→自攻螺丝封板→涂刷防锈漆→预留检修口→现场清理→施工自检； 2.合格标准：符合施工图要求，预留检修口。 | G54: =#REF! -> #REF!
A55: 浴缸基座及安装（三面靠墙） | B55: 个 | C55: 4800 | D55: 2米以内按个数计算 超出部分按300元/10cm计算 | E55: 砌砖墙+抹灰+检修口+贴石材（标配石材）+人工+浴缸安装（不含浴缸的供应） | F55: 1.工艺：定位放线→钢管裁切、焊接→自攻螺丝封板→涂刷防锈漆→预留检修口→瓷砖或石材饰面施工→浴缸安装→现场清理→施工自检； 2.合格标准：符合施工图要求，预留检修口，墙面垂直度≤2mm，平整度≤3mm，浴缸安装水平，浴缸与墙面交界处用半透明胶打胶处理，打胶均匀美观，浴缸满水试验无漏水现象。 | G55: =#REF! -> #REF!
A56: 浴缸基座及安装（两面靠墙） | B56: 个 | C56: 5600 | D56: 2米以内按个数计算 超出部分按400元/10cm计算 | E56: 砌砖墙+抹灰+检修口+贴石材（标配石材）+人工+浴缸安装（不含浴缸的供应） | F56: 1.工艺：定位放线→钢管裁切、焊接→自攻螺丝封板→涂刷防锈漆→预留检修口→瓷砖或石材饰面施工→浴缸安装→现场清理→施工自检； 2.合格标准：符合施工图要求，预留检修口，墙面垂直度≤2mm，平整度≤3mm，浴缸安装水平，浴缸与墙面交界处用半透明胶打胶处理，打胶均匀美观，浴缸满水试验无漏水现象。 | G56: =#REF! -> #REF!
A57: 平层水电半改（PPR) | B57: 平米 | C57: 139 | D57: 按合同面积计算，超出标准部分，费用计算规则详见《水电计价标准》 | E57: 包含开槽、开孔、强弱电改造、空开关调试、给排水改造、通水通电测试等 | F57: 1.施工工艺： 开槽开孔：定位→开剔槽→机械开孔→清理→线槽清扫→涂刷界面剂→水泥砂浆或石膏补槽（潮湿位置必须使用水泥砂浆）→表面粘贴专用玻纤网抗裂； 强电改造：定位→PVC塑料线管加工→管道插接固定→穿塑铜线→绝缘导通检验； 弱电改造：定位→PVC塑料线管加工→固定连接→穿单根超五类网络线、光纤线、音箱线、可视线→导通检验； 强弱电箱：空气开关调试、强强弱电线路嵌入箱体； 给水管改造：定位→PP-R管道加工裁切→热熔连接固定→压力测试； 排水管改造：定位→PVC管道加工裁切→连接固定→通排测试。 2.合格标准：管线走向横平竖直，转角处走圆弧弯或S弯。 3.材料包含：阻燃电线、PVC线管、PPR给水管、PVC排水管、底盒等。 | G57: =#REF! -> #REF!
A58: 复式水电半改（PPR) | B58: 平米 | C58: 169 | D58: 按合同面积计算，超出标准部分，费用计算规则详见《水电计价标准》 | E58: 包含开槽、开孔、强弱电改造、空开关调试、给排水改造、通水通电测试等 | F58: 1.施工工艺： 开槽开孔：定位→开剔槽→机械开孔→清理→线槽清扫→涂刷界面剂→水泥砂浆或石膏补槽（潮湿位置必须使用水泥砂浆）→表面粘贴专用玻纤网抗裂； 强电改造：定位→PVC塑料线管加工→管道插接固定→穿塑铜线→更换空开→绝缘导通检验； 弱电改造：定位→PVC塑料线管加工→固定连接→穿单根超五类网络线、光纤线、音箱线、可视线→导通检验； 强弱电箱：空气开关调试、强弱电线路嵌入箱体； 德国TECE给水系统：定位→墙面开槽机顺直线切割开槽→顶面打孔穿管→管路排管一管到底无接头→管路施工走天→厨卫顶面做冷热水分水器→管口采用插接方式施工→压力测试； 排水管改造：定位→PVC管道加工裁切→连接固定→通排测试。 2.合格标准：管线走向横平竖直，转角处走圆弧弯或S弯。 3.材料包含：阻燃电线、PVC线管、PPR给水管、进口TECE一管到底给水管、分集水器、专用管件、PVC排水管、底盒等。 | G58: =#REF! -> #REF!
A59: 平层水电全改（PPR） | B59: 平米 | C59: 259 | D59: 按合同面积计算，超出标准部分，费用计算规则详见《水电计价标准》 | E59: 包含开槽、开孔、强弱电改造、空开关调试、给排水改造、通水通电测试等 | F59: 1.施工工艺： 开槽开孔：定位放线→开剔槽→机械开孔→清理→线槽清扫→水泥砂浆或石膏补槽（潮湿位置必须使用水泥砂浆）→表面粘贴专用玻纤网抗裂。 强电改造：定位→PVC塑料线管加工→管道插接固定→穿塑铜线→并头→烫锡→缠绕PVC绝缘胶带和绝缘胶布→更换空开→绝缘导通检验。 弱电改造：定位→PVC塑料线管加工→固定连接→穿单根超五类网络线、光纤线、音箱线、可视线→导通检验。 强弱电箱移位：人工进行测量定位→弹线→机械开孔→设置过梁→强弱电箱安装→空气开关安装调试、强弱电线路嵌入箱体 给水管改造：定位→PP-R管道加工裁切→热熔连接固定→压力测试 排水管改造：定位→PVC管道加工裁切→连接固定→通排测试，沉箱内必须做暗漏。 2.合格标准：管线走向横平竖直，转角处走圆弧弯或S弯。 3.材料包含：阻燃电线、PVC线管、PPR给水管、PVC排水管、底盒等； | G59: =#REF! -> #REF!
A60: 复式水电全改（PPR） | B60: 平米 | C60: 299 | D60: 按合同面积计算，超出标准部分，费用计算规则详见《水电计价标准》 | E60: 包含开槽、开孔、强弱电改造、空开关调试、给排水改造、通水通电测试等 | F60: 1.施工工艺： 开槽开孔：定位放线→开剔槽→机械开孔→清理→线槽清扫→水泥砂浆或石膏补槽（潮湿位置必须使用水泥砂浆）→表面粘贴专用玻纤网抗裂。 强电改造：定位→PVC塑料线管加工→管道插接固定→穿塑铜线→并头→烫锡→缠绕PVC绝缘胶带和绝缘胶布→更换空开→绝缘导通检验。 弱电改造：定位→PVC塑料线管加工→固定连接→穿单根超五类网络线、光纤线、音箱线、可视线→导通检验。 强弱电箱移位：人工进行测量定位→弹线→机械开孔→设置过梁→强弱电箱安装→空气开关安装调试、强弱电线路嵌入箱体 给水管改造：定位→PP-R管道加工裁切→热熔连接固定→压力测试 排水管改造：定位→PVC管道加工裁切→连接固定→通排测试，沉箱内必须做暗漏。 2.合格标准：管线走向横平竖直，转角处走圆弧弯或S弯。 3.材料包含：阻燃电线、PVC线管、PPR给水管、PVC排水管、底盒等； | G60: =#REF! -> #REF!
A61: 别墅水电全改（PPR） | B61: 平米 | C61: 299 | D61: 按合同面积计算，超出标准部分，费用计算规则详见《水电计价标准》 | E61: 包含开槽、开孔、强弱电改造、空开关调试、给排水改造、通水通电测试等 | F61: 1.施工工艺： 开槽开孔：定位放线→开剔槽→机械开孔→清理→线槽清扫→水泥砂浆或石膏补槽（潮湿位置必须使用水泥砂浆）→表面粘贴专用玻纤网抗裂。 强电改造：定位→PVC塑料线管加工→管道插接固定→穿塑铜线→并头→烫锡→缠绕PVC绝缘胶带和绝缘胶布→更换空开→绝缘导通检验。 弱电改造：定位→PVC塑料线管加工→固定连接→穿单根超五类网络线、光纤线、音箱线、可视线→导通检验。 强弱电箱移位：人工进行测量定位→弹线→机械开孔→设置过梁→强弱电箱安装→空气开关安装调试、强弱电线路嵌入箱体 给水管改造：定位→PP-R管道加工裁切→热熔连接固定→压力测试 排水管改造：定位→PVC管道加工裁切→连接固定→通排测试，沉箱内必须做暗漏。 2.合格标准：管线走向横平竖直，转角处走圆弧弯或S弯。 3.材料包含：阻燃电线、PVC线管、PPR给水管、PVC排水管、底盒等； | G61: =#REF! -> #REF!
A62: 平层水电全改（进口PPR） | B62: 平米 | C62: 289 | D62: 按合同面积计算，超出标准部分，费用计算规则详见《水电计价标准》 | E62: 包含开槽、开孔、强弱电改造、空开关调试、给排水改造、通水通电测试等 | F62: 1.施工工艺： 开槽开孔：定位放线→开剔槽→机械开孔→清理→线槽清扫→水泥砂浆或石膏补槽（潮湿位置必须使用水泥砂浆）→表面粘贴专用玻纤网抗裂。 强电改造：定位→PVC塑料线管加工→管道插接固定→穿塑铜线→并头→烫锡→缠绕PVC绝缘胶带和绝缘胶布→更换空开→绝缘导通检验。 弱电改造：定位→PVC塑料线管加工→固定连接→穿单根超五类网络线、光纤线、音箱线、可视线→导通检验。 强弱电箱移位：人工进行测量定位→弹线→机械开孔→设置过梁→强弱电箱安装→空气开关安装调试、强弱电线路嵌入箱体 给水管改造：定位→PP-R管道加工裁切→热熔连接固定→压力测试 排水管改造：定位→PVC管道加工裁切→连接固定→通排测试，沉箱内必须做暗漏。 2.合格标准：管线走向横平竖直，转角处走圆弧弯或S弯。 3.材料包含：阻燃电线、PVC线管、PPR给水管、PVC排水管、底盒等； | G62: =#REF! -> #REF!
A63: 复式水电全改（进口PPR） | B63: 平米 | C63: 339 | D63: 按合同面积计算，超出标准部分，费用计算规则详见《水电计价标准》 | E63: 包含开槽、开孔、强弱电改造、空开关调试、给排水改造、通水通电测试等 | F63: 1.施工工艺： 开槽开孔：定位放线→开剔槽→机械开孔→清理→线槽清扫→水泥砂浆或石膏补槽（潮湿位置必须使用水泥砂浆）→表面粘贴专用玻纤网抗裂。 强电改造：定位→PVC塑料线管加工→管道插接固定→穿塑铜线→并头→烫锡→缠绕PVC绝缘胶带和绝缘胶布→更换空开→绝缘导通检验。 弱电改造：定位→PVC塑料线管加工→固定连接→穿单根超五类网络线、光纤线、音箱线、可视线→导通检验。 强弱电箱移位：人工进行测量定位→弹线→机械开孔→设置过梁→强弱电箱安装→空气开关安装调试、强弱电线路嵌入箱体 给水管改造：定位→PP-R管道加工裁切→热熔连接固定→压力测试 排水管改造：定位→PVC管道加工裁切→连接固定→通排测试，沉箱内必须做暗漏。 2.合格标准：管线走向横平竖直，转角处走圆弧弯或S弯。 3.材料包含：阻燃电线、PVC线管、PPR给水管、PVC排水管、底盒等； | G63: =#REF! -> #REF!
A64: 别墅水电全改（进口PPR） | B64: 平米 | C64: 339 | D64: 按合同面积计算，超出标准部分，费用计算规则详见《水电计价标准》 | E64: 包含开槽、开孔、强弱电改造、空开关调试、给排水改造、通水通电测试等 | F64: 1.施工工艺： 开槽开孔：定位放线→开剔槽→机械开孔→清理→线槽清扫→水泥砂浆或石膏补槽（潮湿位置必须使用水泥砂浆）→表面粘贴专用玻纤网抗裂。 强电改造：定位→PVC塑料线管加工→管道插接固定→穿塑铜线→并头→烫锡→缠绕PVC绝缘胶带和绝缘胶布→更换空开→绝缘导通检验。 弱电改造：定位→PVC塑料线管加工→固定连接→穿单根超五类网络线、光纤线、音箱线、可视线→导通检验。 强弱电箱移位：人工进行测量定位→弹线→机械开孔→设置过梁→强弱电箱安装→空气开关安装调试、强弱电线路嵌入箱体 给水管改造：定位→PP-R管道加工裁切→热熔连接固定→压力测试 排水管改造：定位→PVC管道加工裁切→连接固定→通排测试，沉箱内必须做暗漏。 2.合格标准：管线走向横平竖直，转角处走圆弧弯或S弯。 3.材料包含：阻燃电线、PVC线管、PPR给水管、PVC排水管、底盒等； | G64: =#REF! -> #REF!
... A204: 单层石膏板基层 | B204: 平米 | C204: 88 | D204: 按施工面积计算 | E204: 包含石膏板基层施工 | F204: 1.工艺：测量、定位→板材封面（石膏板）→施工自检； 2.合格标准：平整度误差3mm以内，垂直度误差2mm以内。 | G204: =#REF! -> #REF!
A205: 石膏板水缝拉槽处理 | B205: 米 | C205: 16 | D205: 按延长米计算 | E205: 包含基层拉槽处理等 | F205: 0 | G205: =#REF! -> #REF!
A206: 单层石膏板基层+拉槽处理 | B206: 平米 | C206: 158 | D206: 按施工面积计算 | E206: 包含石膏板基层施工及留缝处理 | F206: 1.工艺：测量、定位→板材封面（石膏板）、留缝处理→施工自检； 2.合格标准：平整度误差3mm以内，垂直度误差2mm以内。 | G206: =#REF! -> #REF!
...
