Workbook
Name 吊顶升级: [2]参数表!$K$3:$K$26
Name 综合单价: 分项报价表!$M:$M
Name 预算工程量: 分项报价表!$I:$I
Name 主材单价: 分项报价表!$J:$J
Name 主材损耗率: 分项报价表!$K:$K
Name 施工单价: 分项报价表!$L:$L

Sheet 分项报价表
A1: 分项报价参考表 （小红书：稳哥讲装修）
A2: 序号 | B2: 空间名称 | C2: 项目类型 | D2: 施工部位 | E2: 施工内容 | F2: 项目特征 | G2: 计算规则 | H2: 单位 | I2: 工程量 | J2: 主材单价 | K2: 主材 损耗率 | L2: 施工单价 | M2: 综合单价 | N2: 合计
A3: 一 | B3: 土建改造 | D3: （按实收方） | N3: =SUM(N4:N20) -> 0
A4: 1 | B4: 全屋 | C4: 土建改造 | D4: 打拆 | E4: 墙体拆除（120墙） | F4: =VLOOKUP($E4,[2]收费标准!$D:$K,5,0) -> 拆除120墙体 | G4: =VLOOKUP($E4,[2]收费标准!$D:$K,4,0) -> 按拆除面积计算，厚度超出部分按比例折算 | H4: =VLOOKUP($E4,[2]收费标准!$D:$K,2,0) -> 平米 | N4: =IFERROR(预算工程量*综合单价,"") -> 0
A5: 2 | B5: 全屋 | C5: 土建改造 | D5: 打拆 | E5: 墙体拆除（240墙） | F5: =VLOOKUP($E5,[2]收费标准!$D:$K,5,0) -> 拆除240墙体 | G5: =VLOOKUP($E5,[2]收费标准!$D:$K,4,0) -> 按拆除面积计算，厚度超出部分按比例折算 | H5: =VLOOKUP($E5,[2]收费标准!$D:$K,2,0) -> 平米 | N5: =IFERROR(预算工程量*综合单价,"") -> 0
A6: 3 | B6: 全屋 | C6: 土建改造 | D6: 打拆 | E6: 拆除外墙砖 | F6: =VLOOKUP($E6,[2]收费标准!$D:$K,5,0) -> 拆除外墙砖 | G6: =VLOOKUP($E6,[2]收费标准!$D:$K,4,0) -> 按拆除面积计算 | H6: =VLOOKUP($E6,[2]收费标准!$D:$K,2,0) -> 平米 | N6: =IFERROR(预算工程量*综合单价,"") -> 0
A7: 4 | B7: 全屋（待队长现场确认是否产生此费用） | C7: 土建改造 | D7: 打拆 | E7: 拆除保温层 | F7: =VLOOKUP($E7,[2]收费标准!$D:$K,5,0) -> 拆除保温层或外墙漆 | G7: =VLOOKUP($E7,[2]收费标准!$D:$K,4,0) -> 按拆除面积计算 适用于常规保温层拆除，若有钢丝网则按60元/平米计费 | H7: =VLOOKUP($E7,[2]收费标准!$D:$K,2,0) -> 平米 | N7: =IFERROR(预算工程量*综合单价,"") -> 0
A8: 5 | B8: 全屋 | C8: 土建改造 | D8: 打拆 | E8: 拆除混凝土墙及飘窗台 | F8: =VLOOKUP($E8,[2]收费标准!$D:$K,5,0) -> 拆除混凝土墙或飘窗台，需客户签署免责协议，并需客户取得物业的签字同意 | G8: =VLOOKUP($E8,[2]收费标准!$D:$K,4,0) -> 按拆除面积计算，飘窗台按展开面积计算 砖砌体按230元/平计算，混凝土飘窗按400元/平计算，不足1平米按1平米计算 | H8: =VLOOKUP($E8,[2]收费标准!$D:$K,2,0) -> 平米
A9: 6 | B9: 全屋 | C9: 土建改造 | D9: 打拆 | E9: 拆除混凝土梁、柱 | F9: =VLOOKUP($E9,[2]收费标准!$D:$K,5,0) -> 拆除钢筋混凝土地梁、二次结构的构造柱等（不包含主体结构、承重结构、外立面结构） | G9: =VLOOKUP($E9,[2]收费标准!$D:$K,4,0) -> 3米以内按根数计算,超出3米的部分按100元/米计费 | H9: =VLOOKUP($E9,[2]收费标准!$D:$K,2,0) -> 根
A10: 7 | B10: 全屋 | C10: 土建改造 | D10: 打拆 | E10: 拆除室外/室内楼梯 | F10: =VLOOKUP($E10,[2]收费标准!$D:$K,5,0) -> 包含室外/室内楼梯拆除、现场清理 | G10: =VLOOKUP($E10,[2]收费标准!$D:$K,4,0) -> 按踏步数计算 | H10: =VLOOKUP($E10,[2]收费标准!$D:$K,2,0) -> 步
A11: 8 | B11: 全屋 | C11: 土建改造 | D11: 打拆 | E11: 门窗、栏杆拆除 | F11: =VLOOKUP($E11,[2]收费标准!$D:$K,5,0) -> 拆除门、门套及门套基层，拆除防护栏杆 | G11: =VLOOKUP($E11,[2]收费标准!$D:$K,4,0) -> 1.按拆除门窗扇的个数计算 2.栏杆2米以内，超出按30元/米计费 3.客户不要的工人自行处理，不予收费 | H11: 米
A12: 9 | B12: 全屋（待队长现场确认是否产生此费用） | C12: 土建改造 | D12: 新建 | E12: 空鼓拆除及修复 | F12: =VLOOKUP($E12,[2]收费标准!$D:$K,5,0) -> 空鼓拆除及修复处理等 | G12: =VLOOKUP($E12,[2]收费标准!$D:$K,4,0) -> 单处空鼓面积小于1㎡按1㎡计算，大于1㎡按实际面积计算 | H12: =VLOOKUP($E12,[2]收费标准!$D:$K,2,0) -> 平米
A13: 10 | B13: 全屋 | C13: 土建改造 | D13: 新建 | E13: 新建120墙（轻质砖） | F13: =VLOOKUP($E13,[2]收费标准!$D:$K,5,0) -> 包含铲墙皮、植筋、墙体砌筑、新旧墙体交接处挂网、墙面抹灰 | G13: =VLOOKUP($E13,[2]收费标准!$D:$K,4,0) -> 按新建面积计算 主要用于厨卫及生活阳台以外的非承重区域 | H13: =VLOOKUP($E13,[2]收费标准!$D:$K,2,0) -> 平米
A14: 11 | B14: 全屋 | C14: 土建改造 | D14: 新建 | E14: 新建240墙（轻质砖） | F14: =VLOOKUP($E14,[2]收费标准!$D:$K,5,0) -> 包含铲墙皮、植筋、墙体砌筑、新旧墙体交接处挂网、墙面抹灰 | G14: =VLOOKUP($E14,[2]收费标准!$D:$K,4,0) -> 按新建面积计算 主要用于厨卫及生活阳台以外的非承重区域 | H14: =VLOOKUP($E14,[2]收费标准!$D:$K,2,0) -> 平米
A15: 12 | B15: 全屋 | C15: 土建改造 | D15: 新建 | E15: 门窗洞修补（水泥砂浆） | F15: =VLOOKUP($E15,[2]收费标准!$D:$K,5,0) -> 水泥砂浆抹灰修补，适用于打拆后的门窗洞修补，不含过梁 | G15: =VLOOKUP($E15,[2]收费标准!$D:$K,4,0) -> 按个数计算 | H15: =VLOOKUP($E15,[2]收费标准!$D:$K,2,0) -> 个
A16: 5 | B16: 厨房卫生间（其他区域待队长现场确认是否产生此费用） | C16: 门 | D16: 新建 | E16: 水泥砂浆精找平 | G16: 按施工面积计算 | H16: 平米
A17: 6 | B17: 厨房、客卫、主卫、主卧、儿童房等 | C17: 土建改造 | D17: 新建 | E17: 门过梁施工（1.2米） | F17: =VLOOKUP($E17,[2]收费标准!$D:$K,5,0) -> 门洞宽900mm以内 | G17: =VLOOKUP($E17,[2]收费标准!$D:$K,4,0) -> 按根数计算，墙厚140mm以内的墙使用1根，墙厚>140mm的墙使用2根 | H17: =VLOOKUP($E17,[2]收费标准!$D:$K,2,0) -> 根
A18: 7 | B18: 次卫 | C18: 土建改造 | D18: 新建 | E18: 壁龛（300*300以内） | F18: =VLOOKUP($E18,[2]收费标准!$D:$K,5,0) -> 墙面防水、瓷砖胶薄贴法施工，含瓷砖加工、缝隙清理、瓷砖面清理、阳角保护等 | G18: =VLOOKUP($E18,[2]收费标准!$D:$K,4,0) -> 按壁龛格数计算，超出300mm*300mm以外的部分按198元/10cm计算 | H18: =VLOOKUP($E18,[2]收费标准!$D:$K,2,0) -> 格 | N18: =IFERROR('[2]02-个性需求报价明细'!预算工程量*综合单价,"") -> 0
A19: 8 | B19: 厨房、生活阳台 | C19: 土建改造 | D19: 回填找平 | E19: 陶粒回填+保护层（厚度150mm以内） | F19: =VLOOKUP($E19,[2]收费标准!$D:$K,5,0) -> 陶粒回填找平 | G19: =VLOOKUP($E19,[2]收费标准!$D:$K,4,0) -> 按回填区域面积计算 | H19: =VLOOKUP($E19,[2]收费标准!$D:$K,2,0) -> 平米 | N19: =IFERROR(预算工程量*综合单价,"") -> 0
A20: 8 | B20: 全屋（待队长现场确认是否产生此费用） | C20: 土建改造 | D20: 回填找平 | E20: 地暖前地面粗找平（厚度50mm以内） | F20: =VLOOKUP($E20,[2]收费标准!$D:$K,5,0) -> 地暖施工前地面水泥河沙找平处理 | G20: =VLOOKUP($E20,[2]收费标准!$D:$K,4,0) -> 按施工面积计算 | H20: =VLOOKUP($E20,[2]收费标准!$D:$K,2,0) -> 平米
A21: 二 | B21: 空间配置升级 | N21: =N24 -> 0
A22: 2） | B22: 卧室扩入公区 | N22: =SUM(N23:N23) -> 0
A23: 2.1 | C23: 户型扩改 | D23: 地面 | G23: 按施工面积计算 | H23: 平米 | N23: =IFERROR(预算工程量*综合单价,"") -> 0
A24: 1） | B24: 空间扩大 | N24: =SUM(N25:N26) -> 0
A25: 1.1 | B25: 厨房扩大 | C25: 户型扩改 | D25: 墙顶地 | G25: 按施工面积计算 | H25: 平米
A26: 1.2 | B26: 主卫扩大 | C26: 户型扩改 | D26: 墙顶地 | G26: 按施工面积计算 | H26: 平米
A27: 三 | B27: 厨房门 / 其他门扩大新增
A28: 1 | B28: 室内门 | D28: 门 | G28: 按平米计算 | H28: 平米
A29: 2 | B29: 厨卫门 | D29: 门 | G29: 按平米计算 | H29: 平米
A30: 四 | B30: 个性选择 | N30: =SUM(N31,N39,N43,N45,N47,) -> 0
A31: 1） | B31: 吊顶 | N31: =SUM(N32:N37) -> 0
A32: 1.1 | B32: 全屋 | C32: 吊顶 | D32: 顶面 | E32: 增加平顶 | F32: =VLOOKUP($E32,[2]收费标准!$D:$K,5,0) -> 包含打眼、吊筋、主副龙骨、单层石膏板安装、转角加固等 | G32: =VLOOKUP($E32,[2]收费标准!$D:$K,4,0) -> 按展开面积计算 | H32: =VLOOKUP($E32,[2]收费标准!$D:$K,2,0) -> 平米
A33: 1.2 | B33: 全屋 | C33: 吊顶 | D33: 顶面 | E33: 平顶上增加灯槽 | F33: =VLOOKUP($E33,[2]收费标准!$D:$K,5,0) -> 包含灯槽制作安装、基层加固等 | G33: =VLOOKUP($E33,[2]收费标准!$D:$K,4,0) -> 按延长米计算 | H33: =VLOOKUP($E33,[2]收费标准!$D:$K,2,0) -> 米
A34: 1.3 | B34: 全屋 | C34: 吊顶 | D34: 顶面 | E34: 增加石膏板眉线 | F34: =VLOOKUP($E34,[2]收费标准!$D:$K,5,0) -> 吊顶一圈、边顶或灯槽反边的眉线制作安装双层石膏板（吊顶单算，这个只是眉线） | G34: =VLOOKUP($E34,[2]收费标准!$D:$K,4,0) -> 按延长米计算 （宽度20mm以内，高度200mm以内，超出费用另计。高度每增加100mm增加15元/米） | H34: =VLOOKUP($E34,[2]收费标准!$D:$K,2,0) -> 米
A35: 1.4 | B35: 全屋 | C35: 吊顶 | D35: 顶面 | E35: 增加窗帘盒 | F35: =VLOOKUP($E35,[2]收费标准!$D:$K,5,0) -> 包含窗帘盒制作安装、基层加固等 | G35: =VLOOKUP($E35,[2]收费标准!$D:$K,4,0) -> 按延长米计算 | H35: =VLOOKUP($E35,[2]收费标准!$D:$K,2,0) -> 米
A36: 1.5 | B36: 全屋 | C36: 吊顶 | D36: 顶面 | E36: 筒射灯 | F36: 甲供 | H36: 个
A37: 1.5 | B37: 全屋 | C37: 吊顶 | D37: 顶面 | E37: 开设备孔（空调/浴霸/暖风机） | F37: =VLOOKUP($E37,[2]收费标准!$D:$K,5,0) -> 包含放线、定位、开孔及加固处理等 | G37: =VLOOKUP($E37,[2]收费标准!$D:$K,4,0) -> 按个数计算 风口长度超出1米的按50元/米计算 | H37: 米
B38: 开空调风口未计入预算。
A39: 2） | B39: 背景墙 | N39: =SUM(N40:N42) -> 0
A40: 2.1 | B40: 全屋 | D40: 墙面 | E40: 墙板/石材 | H40: 平米
...

Sheet 水电报价表
A1: 水电报价表
A2: 序号 | B2: 项目名称 | C2: 计量 单位 | D2: 工程量 | E2: 单价 | F2: 合价 | G2: 计算规则 | H2: 项目特征描述
A3: 1 | B3: 普通插座/备用电源/开关 | C3: 个 | G3: 按点位数计算 | H3: 含面板
A4: 2 | B4: 壁灯电源 | C4: 个 | G4: 按点位数计算 | H4: 不含灯具
A5: 3 | B5: 踏步灯电源 | C5: 个 | G5: 按点位数计算 | H5: 不含灯具
A6: 4 | B6: 大功率电器插座（4平方） | C6: 个 | G6: 按点位数计算,6平方线路按680元/个计算 | H6: 含面板
A7: 5 | B7: 地插 | C7: 个 | G7: 按个数计算 | H7: 含面板
A8: 6 | B8: 普通插座升级USB插座 | C8: 个 | G8: 按个数计算 | H8: 含面板
A9: 7 | B9: 网络电视电话插座 | C9: 个 | G9: 按点位数计算 | H9: 含面板
A10: 8 | B10: 小夜灯 | C10: 个 | G10: 按个数计算 | H10: 含面板
A11: 9 | B11: 平层-电箱全改（合同面积≤150㎡） | C11: 套 | G11: 按套数计算 | H11: 包含强电箱更换、安装、固定、安装空开、排线、接线等
A12: 10 | B12: 平层-电箱全改 | C12: 套 | F12: =IFERROR(E12*D12,0) -> 0 | G12: 按套数计算 复式+500元/户，别墅+1000元/户 | H12: 包含强电箱更换、安装、固定、安装空开、排线、接线等
A13: 11 | B13: 强电箱移位 | C13: 套 | F13: =IFERROR(E13*D13,0) -> 0 | G13: 按套数计算 | H13: 包含开槽移位，排线接线等，不含电箱入户主线，主线部分按时收方包
A14: 12 | B14: 弱电箱移位 | C14: 套 | F14: =IFERROR(E14*D14,0) -> 0 | G14: 按套数计算 | H14: 包含开槽移位，排线接线等，不含网络主线，线路部分按时收方
A15: 13 | B15: 中央空调电源线（内机） | C15: 个 | F15: =IFERROR(E15*D15,0) -> 0 | G15: 按空调内机个数计算 | H15: 包含开槽、布管布线等
A16: 14 | B16: 中央空调电源线（外机） | C16: 个 | F16: =IFERROR(E16*D16,0) -> 0 | G16: 按空调外机个数计算 | H16: 包含开槽、布管布线等
A17: 15 | B17: 大循环水改造 | C17: 户 | F17: =IFERROR(E17*D17,0) -> 0 | G17: 按户数计算 | H17: 包含开槽、布管、管件安装等
A18: 16 | B18: 普通智能开关线路 | C18: 平米 | F18: =IFERROR(E18*D18,0) -> 0 | G18: 按合同面积计算 | H18: 每个开关单独走零线
A19: 17 | B19: 总线智能控制线路 | C19: 平米 | F19: =IFERROR(E19*D19,0) -> 0 | G19: 按合同面积计算（不含专用的弱电控制线） | H19: 每组灯具单独走线至智能控制箱，每个开关单独走线至控制箱，专用的弱电控制线（开关控制线）甲供
A20: 18 | B20: 强弱电排线走天花 | C20: 平米 | F20: =IFERROR(E20*D20,0) -> 0 | G20: 按合同面积计算 | H20: 适用于因开发商原始建筑原因地面无法开槽的项目
